<mujoco model="3_link_robot">
    <!-- Compiler settings -->
    <compiler angle="degree" />
    <option timestep="0.001" gravity="0 0 0" />

    <!-- Asset: Mesh definitions -->
    <asset>
        <mesh name="Base" file="meshes/Base.stl" scale="0.001 0.001 0.001" />
        <mesh name="BottomCircle" file="meshes/BottomCircle.stl" scale="0.001 0.001 0.001" />
        <mesh name="FullCircle" file="meshes/FullCircle.stl" scale="0.001 0.001 0.001" />
        <mesh name="TopStick" file="meshes/TopStick.stl" scale="0.001 0.001 0.001" />
        <mesh name="EndEffector" file="meshes/EndEffector.stl" scale="0.001 0.001 0.001" />
        <mesh name="Pin" file="meshes/Pin.stl" scale="0.001 0.001 0.001" />


        <texture type="skybox" builtin="gradient" rgb1="0.3 0.5 0.7" rgb2="0 0 0" width="512"
            height="3072" />
        <texture type="2d" name="groundplane" builtin="checker" mark="edge" rgb1="0.2 0.3 0.4"
            rgb2="0.1 0.2 0.3"
            markrgb="0.8 0.8 0.8" width="300" height="300" />
        <material name="groundplane" texture="groundplane" texuniform="true" texrepeat="5 5"
            reflectance="0.2" />
    </asset>

    <!-- World settings -->
    <worldbody>
        <!-- Ground plane -->
        <geom name="floor" size="0 0 0.05" type="plane" material="groundplane" condim="1" />
        <camera name="PerspectiveCamera" mode="fixed" pos="0 0 6" euler="0 -20 90" />

        <!-- Base body -->
        <body name="BASE" pos="0 0 0.05" euler="0 0 0">
            <geom name="GB" type="mesh" contype="0" conaffinity="0" mesh="Base" rgba="0.8 0.4 0.2 1" />


            <body name="BOTTOMCIRCLE" pos="0 0 0.07" euler="0 0 0">
                <geom name="GBC" type="mesh" mesh="BottomCircle" rgba="1 1 1 1" condim="1"
                    contype="0" conaffinity="0" />
                <!-- <inertial pos="    -2.9206e-05  -7.8100e-07   1.7067e-05" mass="0.3465"
                    diaginertia="8.6730e-04 3.9840e-04  0.001" /> -->
                <joint name="jointBC" type="hinge" pos="0 0 0" axis="0 0 1" damping="0.8"
                    stiffness="10" limited="true" range="-90 90" />


                <!-- (FULLCIRCLE) -->
                <body name="FULLCIRCLE" pos="0 0.081 0.108" euler="90 0 0">
                    <geom name="GFC" type="mesh" mesh="FullCircle" rgba="0.5 0.6 0.2 1" />
                    <!-- <inertial pos=" 0  0 0.0084" mass="0.218971"
                        diaginertia="   2.7140e-04 2.7140e-04  4.4400e-04" /> -->


                    <!-- TOP STICK  -->
                    <body name="TOPSTICK" pos="0 0.0 0.061" euler="270 0 0">
                        <geom name="GT" type="mesh" mesh="TopStick" rgba=".1 0.5 1 1" condim="1"
                            contype="0" conaffinity="0" />
                        <!-- <inertial pos="0.1062  1.672e-09    -0.015e-03" mass="0.0407"
                            diaginertia="   8.5541e-07    1.6160e-04     1.6190e-04" /> -->
                        <joint name="jointTS" type="hinge" pos="0 0 0.0" axis="0 1 0"
                            damping=".5" stiffness="10.0" />


                        <!-- END EFFECTOR -->
                        <body name="ENDEFFECTOR" pos="0.2125 -0.0175 0" euler="0 0 0">
                            <geom name="GE" type="mesh" mesh="EndEffector" rgba="0.5 0.1 0.3 1" />
                            <!-- <inertial pos="  -4.3e-05  2.3100e-04  -0.0670" mass="0.29581"
                                    diaginertia="7.4267e-05  7.4248e-05  3.8531e-07" /> -->
                            <joint name="jointE" type="hinge" pos="0 0 0.0" axis="0 1 0"
                                damping=".1" stiffness="5.0" />
                        </body>
                    </body>
                </body>
            </body>
        </body>

        <!-- Lighting -->
        <light pos="0 0 2" dir="0 0 -1" />
        <light pos="0 1 2" dir="0 0 -1" />
        <light pos="0 -1 2" dir="0 0 -1" />
        <light pos="1 0 2" dir="0 0 -1" />
        <light pos="-1 0 2" dir="0 0 -1" />


    </worldbody>
    <!-- Equality constraint for JointS and JointSS -->
    <!-- <equality>
        <joint joint1="jointTS" joint2="jointP" polycoef="0 -1 0 0 0"
            solimp=".7 0.1 0.05 1 5"
            solref=".01 0.001"
        />
    </equality> -->


    <!-- Contact exclusions to prevent unwanted interactions -->
    <contact>
        <exclude body1="BOTTOMCIRCLE" body2="BASE" />
        <exclude body1="BOTTOMCIRCLE" body2="FULLCIRCLE" />
        <exclude body1="BOTTOMCIRCLE" body2="TOPSTICK" />
        <exclude body1="BOTTOMCIRCLE" body2="ENDEFFECTOR" />

        <exclude body1="FULLCIRCLE" body2="TOPSTICK" />
        <exclude body1="FULLCIRCLE" body2="ENDEFFECTOR" />
        <exclude body1="TOPSTICK" body2="ENDEFFECTOR" />


    </contact>
    <!-- Actuator definitions -->
    <actuator>
        <motor name="Pos1" joint="jointBC" ctrllimited="true" ctrlrange="-50 50"
            gear="1 0 0 0 0 0" />
        <motor name="Pos2" joint="jointTS" ctrllimited="true" ctrlrange="-6 5" gear="1 0 0 0 0 0" />
        <motor name="Pos3" joint="jointE" ctrllimited="true" ctrlrange="-3 3" gear="1 0 0 0 0 0" />
    </actuator>

</mujoco>